<?xml version="1.0"?>
<!-- GIEMON 6-DOF manipulator — articulation spec (PARITY ORACLE).
     clj/edn が主 (ADR-0040/0042/0046): 正本は giemon_arm6.edn。この URDF は
     互換ローダの parity oracle として残し、from_edn(edn) == parse_urdf(urdf) を検証する。
     Parsed at runtime by kami_articulated::parse_urdf and driven by the
     kami-genesis 3-D reduced-coordinate spatial solver (RNEA + CRBA) with the
     contact/collision solver. Links stack along +z; a typical 6-DOF wrist
     (z, y, y, z, y, z). Units: metres / kg / kg·m². -->
<robot name="giemon_arm6">

  <link name="base_link">
    <inertial>
      <origin xyz="0 0 0.04" rpy="0 0 0"/>
      <mass value="2.0"/>
      <inertia ixx="0.004" iyy="0.004" izz="0.004" ixy="0" ixz="0" iyz="0"/>
    </inertial>
  </link>

  <joint name="j1" type="revolute">
    <parent link="base_link"/>
    <child link="link1"/>
    <origin xyz="0 0 0.08" rpy="0 0 0"/>
    <axis xyz="0 0 1"/>
    <limit lower="-3.0" upper="3.0" effort="40" velocity="3"/>
    <dynamics damping="0.06"/>
  </joint>
  <link name="link1">
    <inertial>
      <origin xyz="0 0 0.03" rpy="0 0 0"/>
      <mass value="0.6"/>
      <inertia ixx="0.0012" iyy="0.0012" izz="0.0008" ixy="0" ixz="0" iyz="0"/>
    </inertial>
  </link>

  <joint name="j2" type="revolute">
    <parent link="link1"/>
    <child link="link2"/>
    <origin xyz="0 0 0.06" rpy="0 0 0"/>
    <axis xyz="0 1 0"/>
    <limit lower="-2.2" upper="2.2" effort="40" velocity="3"/>
    <dynamics damping="0.08"/>
  </joint>
  <link name="link2">
    <inertial>
      <origin xyz="0 0 0.09" rpy="0 0 0"/>
      <mass value="0.5"/>
      <inertia ixx="0.0030" iyy="0.0030" izz="0.0006" ixy="0" ixz="0" iyz="0"/>
    </inertial>
  </link>

  <joint name="j3" type="revolute">
    <parent link="link2"/>
    <child link="link3"/>
    <origin xyz="0 0 0.18" rpy="0 0 0"/>
    <axis xyz="0 1 0"/>
    <limit lower="-2.5" upper="2.5" effort="30" velocity="3"/>
    <dynamics damping="0.06"/>
  </joint>
  <link name="link3">
    <inertial>
      <origin xyz="0 0 0.07" rpy="0 0 0"/>
      <mass value="0.35"/>
      <inertia ixx="0.0016" iyy="0.0016" izz="0.0004" ixy="0" ixz="0" iyz="0"/>
    </inertial>
  </link>

  <joint name="j4" type="revolute">
    <parent link="link3"/>
    <child link="link4"/>
    <origin xyz="0 0 0.14" rpy="0 0 0"/>
    <axis xyz="0 0 1"/>
    <limit lower="-3.0" upper="3.0" effort="14" velocity="4"/>
    <dynamics damping="0.04"/>
  </joint>
  <link name="link4">
    <inertial>
      <origin xyz="0 0 0.04" rpy="0 0 0"/>
      <mass value="0.22"/>
      <inertia ixx="0.0006" iyy="0.0006" izz="0.0003" ixy="0" ixz="0" iyz="0"/>
    </inertial>
  </link>

  <joint name="j5" type="revolute">
    <parent link="link4"/>
    <child link="link5"/>
    <origin xyz="0 0 0.10" rpy="0 0 0"/>
    <axis xyz="0 1 0"/>
    <limit lower="-2.0" upper="2.0" effort="10" velocity="4"/>
    <dynamics damping="0.03"/>
  </joint>
  <link name="link5">
    <inertial>
      <origin xyz="0 0 0.03" rpy="0 0 0"/>
      <mass value="0.16"/>
      <inertia ixx="0.0003" iyy="0.0003" izz="0.0002" ixy="0" ixz="0" iyz="0"/>
    </inertial>
  </link>

  <joint name="j6" type="revolute">
    <parent link="link5"/>
    <child link="link6"/>
    <origin xyz="0 0 0.06" rpy="0 0 0"/>
    <axis xyz="0 0 1"/>
    <limit lower="-3.0" upper="3.0" effort="6" velocity="5"/>
    <dynamics damping="0.02"/>
  </joint>
  <link name="link6">
    <inertial>
      <origin xyz="0 0 0.025" rpy="0 0 0"/>
      <mass value="0.12"/>
      <inertia ixx="0.0002" iyy="0.0002" izz="0.0001" ixy="0" ixz="0" iyz="0"/>
    </inertial>
  </link>

</robot>
